import { describe, it, expect, vi, beforeEach } from 'vitest'
import { mount } from '@vue/test-utils'

// Mock error boundary component
const ErrorBoundary = {
    name: 'ErrorBoundary',
    template: `
    <div>
      <div v-if="hasError" data-testid="error-boundary">
        <h2>Something went wrong</h2>
        <p>{{ errorMessage }}</p>
        <button @click="retry" data-testid="retry-button">Retry</button>
      </div>
      <slot v-else />
    </div>
  `,
    data() {
        return {
            hasError: false,
            errorMessage: '',
        }
    },
    methods: {
        retry() {
            this.hasError = false
            this.errorMessage = ''
            this.$emit('retry')
        },
    },
    errorCaptured(error: Error) {
        this.hasError = true
        this.errorMessage = error.message
        return false
    },
}

// Mock component that throws error
const ErrorThrowingComponent = {
    name: 'ErrorThrowingComponent',
    template: '<div>{{ computedValue }}</div>',
    computed: {
        computedValue() {
            if (this.shouldThrow) {
                throw new Error('Test error')
            }
            return 'Normal content'
        },
    },
    props: {
        shouldThrow: {
            type: Boolean,
            default: false,
        },
    },
}

describe('Error Handling Integration', () => {
    let mockErrorHandler: any
    let mockToast: any

    beforeEach(() => {
        vi.clearAllMocks()

        mockErrorHandler = {
            handleError: vi.fn().mockReturnValue({
                message: 'Handled error message',
                type: 'error',
                recoverable: true,
            }),
        }

        mockToast = {
            error: vi.fn(),
            success: vi.fn(),
            warning: vi.fn(),
        }

        global.useErrorHandler = vi.fn(() => mockErrorHandler)
        global.useToast = vi.fn(() => mockToast)
    })

    describe('Error Boundary', () => {
        it('catches and displays component errors', async () => {
            const wrapper = mount(ErrorBoundary, {
                slots: {
                    default: () => mount(ErrorThrowingComponent, {
                        props: { shouldThrow: true },
                    }).html(),
                },
            })

            // Simulate error in child component
            const errorBoundary = wrapper.findComponent(ErrorBoundary)
            errorBoundary.vm.hasError = true
            errorBoundary.vm.errorMessage = 'Test error'

            await wrapper.vm.$nextTick()

            const errorElement = wrapper.find('[data-testid="error-boundary"]')
            expect(errorElement.exists()).toBe(true)
            expect(errorElement.text()).toContain('Something went wrong')
            expect(errorElement.text()).toContain('Test error')
        })

        it('provides retry functionality', async () => {
            const wrapper = mount(ErrorBoundary, {
                slots: {
                    default: '<div>Normal content</div>',
                },
            })

            // Simulate error state
            const errorBoundary = wrapper.findComponent(ErrorBoundary)
            errorBoundary.vm.hasError = true
            errorBoundary.vm.errorMessage = 'Test error'

            await wrapper.vm.$nextTick()

            const retryButton = wrapper.find('[data-testid="retry-button"]')
            expect(retryButton.exists()).toBe(true)

            await retryButton.trigger('click')

            expect(errorBoundary.vm.hasError).toBe(false)
            expect(errorBoundary.vm.errorMessage).toBe('')
        })
    })

    describe('Global Error Handler', () => {
        it('handles JavaScript errors globally', () => {
            const error = new Error('Global JavaScript error')

            // Simulate global error handler
            const handleGlobalError = (error: Error) => {
                mockErrorHandler.handleError(error, 'javascript')
                mockToast.error('An unexpected error occurred')
            }

            handleGlobalError(error)

            expect(mockErrorHandler.handleError).toHaveBeenCalledWith(error, 'javascript')
            expect(mockToast.error).toHaveBeenCalledWith('An unexpected error occurred')
        })

        it('handles unhandled promise rejections', () => {
            const error = new Error('Unhandled promise rejection')

            // Simulate unhandled promise rejection handler
            const handleUnhandledRejection = (event: any) => {
                mockErrorHandler.handleError(event.reason, 'promise')
                mockToast.error('A network error occurred')
            }

            handleUnhandledRejection({ reason: error })

            expect(mockErrorHandler.handleError).toHaveBeenCalledWith(error, 'promise')
            expect(mockToast.error).toHaveBeenCalledWith('A network error occurred')
        })
    })

    describe('API Error Handling', () => {
        it('handles network errors gracefully', async () => {
            const mockApi = {
                getPosts: vi.fn().mockRejectedValue(new Error('Network error')),
            }

            global.useApi = vi.fn(() => mockApi)

            const handleApiError = async () => {
                try {
                    await mockApi.getPosts()
                } catch (error) {
                    const handledError = mockErrorHandler.handleError(error, 'network')
                    mockToast.error(handledError.message)
                }
            }

            await handleApiError()

            expect(mockErrorHandler.handleError).toHaveBeenCalledWith(
                expect.any(Error),
                'network'
            )
            expect(mockToast.error).toHaveBeenCalledWith('Handled error message')
        })

        it('handles authentication errors', async () => {
            const authError = new Error('Unauthorized')
            authError.name = 'AuthenticationError'

            const mockApi = {
                getProtectedData: vi.fn().mockRejectedValue(authError),
            }

            global.useApi = vi.fn(() => mockApi)

            const handleAuthError = async () => {
                try {
                    await mockApi.getProtectedData()
                } catch (error) {
                    const handledError = mockErrorHandler.handleError(error, 'auth')
                    mockToast.error(handledError.message)
                }
            }

            await handleAuthError()

            expect(mockErrorHandler.handleError).toHaveBeenCalledWith(authError, 'auth')
            expect(mockToast.error).toHaveBeenCalledWith('Handled error message')
        })

        it('handles validation errors', async () => {
            const validationError = new Error('Validation failed')
            validationError.name = 'ValidationError'

            const mockApi = {
                submitForm: vi.fn().mockRejectedValue(validationError),
            }

            global.useApi = vi.fn(() => mockApi)

            const handleValidationError = async () => {
                try {
                    await mockApi.submitForm()
                } catch (error) {
                    const handledError = mockErrorHandler.handleError(error, 'validation')
                    mockToast.warning(handledError.message)
                }
            }

            await handleValidationError()

            expect(mockErrorHandler.handleError).toHaveBeenCalledWith(validationError, 'validation')
            expect(mockToast.warning).toHaveBeenCalledWith('Handled error message')
        })
    })

    describe('Media Error Handling', () => {
        it('handles image loading errors', async () => {
            const mockMediaErrorHandler = {
                handleMediaError: vi.fn().mockResolvedValue('/fallback-image.jpg'),
            }

            global.useMediaErrorHandler = vi.fn(() => mockMediaErrorHandler)

            const handleImageError = async (src: string) => {
                const fallbackSrc = await mockMediaErrorHandler.handleMediaError(src, 'image')
                return fallbackSrc
            }

            const result = await handleImageError('/broken-image.jpg')

            expect(mockMediaErrorHandler.handleMediaError).toHaveBeenCalledWith('/broken-image.jpg', 'image')
            expect(result).toBe('/fallback-image.jpg')
        })

        it('handles IPX optimization errors', async () => {
            const mockIPXFallback = {
                handleIPXError: vi.fn().mockReturnValue('/original-image.jpg'),
            }

            global.useIPXFallback = vi.fn(() => mockIPXFallback)

            const handleIPXError = (src: string) => {
                return mockIPXFallback.handleIPXError(src)
            }

            const result = handleIPXError('/_ipx/w_300/broken-image.jpg')

            expect(mockIPXFallback.handleIPXError).toHaveBeenCalledWith('/_ipx/w_300/broken-image.jpg')
            expect(result).toBe('/original-image.jpg')
        })
    })

    describe('Error Recovery', () => {
        it('provides recovery actions for different error types', async () => {
            const mockErrorRecovery = {
                handleError: vi.fn(),
                getRecoveryActions: vi.fn().mockReturnValue([
                    { label: 'Retry', action: 'retry' },
                    { label: 'Go Home', action: 'navigate' },
                ]),
            }

            global.useErrorHandler = vi.fn(() => mockErrorRecovery)

            const error = new Error('Network error')
            await mockErrorRecovery.handleError(error, 'network')
            const actions = mockErrorRecovery.getRecoveryActions()

            expect(actions).toHaveLength(2)
            expect(actions[0]).toEqual({ label: 'Retry', action: 'retry' })
            expect(actions[1]).toEqual({ label: 'Go Home', action: 'navigate' })
        })

        it('executes recovery actions', async () => {
            const mockRouter = {
                push: vi.fn(),
            }

            global.useRouter = vi.fn(() => mockRouter)

            const executeRecoveryAction = (action: string) => {
                switch (action) {
                    case 'retry':
                        // Retry logic
                        break
                    case 'navigate':
                        mockRouter.push('/')
                        break
                }
            }

            executeRecoveryAction('navigate')

            expect(mockRouter.push).toHaveBeenCalledWith('/')
        })
    })

    describe('Error Logging and Monitoring', () => {
        it('logs errors for monitoring', () => {
            const mockLogger = {
                error: vi.fn(),
                warn: vi.fn(),
                info: vi.fn(),
            }

            const logError = (error: Error, context: any) => {
                mockLogger.error('Error occurred', {
                    message: error.message,
                    stack: error.stack,
                    context,
                    timestamp: new Date().toISOString(),
                })
            }

            const error = new Error('Test error')
            const context = { page: 'home', action: 'load' }

            logError(error, context)

            expect(mockLogger.error).toHaveBeenCalledWith('Error occurred', {
                message: 'Test error',
                stack: error.stack,
                context,
                timestamp: expect.any(String),
            })
        })

        it('tracks error statistics', () => {
            const mockErrorStats = {
                increment: vi.fn(),
                getStats: vi.fn().mockReturnValue({
                    total: 5,
                    byType: { network: 3, auth: 1, validation: 1 },
                    recent: [],
                }),
            }

            const trackError = (error: Error, type: string) => {
                mockErrorStats.increment(type)
            }

            trackError(new Error('Network error'), 'network')
            trackError(new Error('Auth error'), 'auth')

            expect(mockErrorStats.increment).toHaveBeenCalledWith('network')
            expect(mockErrorStats.increment).toHaveBeenCalledWith('auth')
        })
    })
})